
| distributed init (rank 0): env://
Error in sys.excepthook:
Traceback (most recent call last):
  File "/home/mingyuan/anaconda3/envs/deit/lib/python3.8/site-packages/wandb/sdk/lib/exit_hooks.py", line 52, in exc_handler
    traceback.print_exception(exc_type, exc, tb)
  File "/home/mingyuan/anaconda3/envs/deit/lib/python3.8/traceback.py", line 103, in print_exception
    for line in TracebackException(
  File "/home/mingyuan/anaconda3/envs/deit/lib/python3.8/traceback.py", line 508, in __init__
    self.stack = StackSummary.extract(
  File "/home/mingyuan/anaconda3/envs/deit/lib/python3.8/traceback.py", line 366, in extract
    f.line
  File "/home/mingyuan/anaconda3/envs/deit/lib/python3.8/traceback.py", line 288, in line
    self._line = linecache.getline(self.filename, self.lineno).strip()
  File "/home/mingyuan/anaconda3/envs/deit/lib/python3.8/linecache.py", line 17, in getline
    if 1 <= lineno <= len(lines):
KeyboardInterrupt
Original exception was:
Traceback (most recent call last):
  File "main.py", line 863, in <module>
    if __name__ == '__main__':
  File "main.py", line 295, in main
  File "/home/mingyuan/lab/deit/utils.py", line 243, in init_distributed_mode
    torch.distributed.init_process_group(backend=args.dist_backend, init_method=args.dist_url,
  File "/home/mingyuan/anaconda3/envs/deit/lib/python3.8/site-packages/torch/distributed/distributed_c10d.py", line 920, in init_process_group
    _store_based_barrier(rank, store, timeout)
  File "/home/mingyuan/anaconda3/envs/deit/lib/python3.8/site-packages/torch/distributed/distributed_c10d.py", line 445, in _store_based_barrier
    time.sleep(0.01)
KeyboardInterrupt